<?xml version="1.0" ?>
<sdf version="1.7">
  <model name="diffdrive_robot">
    <pose>0 0 0.1 0 0 0</pose>
    <link name="chassis">
      <pose>0 0 0.1 0 0 0</pose>
      <inertial>
        <mass>5.0</mass>
      </inertial>
      <collision name="collision">
        <geometry>
          <box><size>0.4 0.3 0.2</size></box>
        </geometry>
      </collision>
      <visual name="visual">
        <geometry>
          <box><size>0.4 0.3 0.2</size></box>
        </geometry>
        <material>
          <ambient>0.1 0.8 0.1 1</ambient>
        </material>
      </visual>
    </link>

    <!-- Left wheel -->
    <link name="left_wheel">
      <pose>0 0.2 0.05 0 0 0</pose>
      <collision name="collision">
        <geometry><cylinder><radius>0.05</radius><length>0.02</length></cylinder></geometry>
      </collision>
      <visual name="visual">
        <geometry><cylinder><radius>0.05</radius><length>0.02</length></cylinder></geometry>
        <material><ambient>0.2 0.2 0.2 1</ambient></material>
      </visual>
    </link>

    <!-- Right wheel -->
    <link name="right_wheel">
      <pose>0 -0.2 0.05 0 0 0</pose>
      <collision name="collision">
        <geometry><cylinder><radius>0.05</radius><length>0.02</length></cylinder></geometry>
      </collision>
      <visual name="visual">
        <geometry><cylinder><radius>0.05</radius><length>0.02</length></cylinder></geometry>
        <material><ambient>0.2 0.2 0.2 1</ambient></material>
      </visual>
    </link>

    <!-- Joints -->
    <joint name="left_wheel_joint" type="revolute">
      <parent>chassis</parent>
      <child>left_wheel</child>
      <axis>
        <xyz>0 1 0</xyz>
        <limit><lower>-1e16</lower><upper>1e16</upper></limit>
      </axis>
    </joint>

    <joint name="right_wheel_joint" type="revolute">
      <parent>chassis</parent>
      <child>right_wheel</child>
      <axis>
        <xyz>0 1 0</xyz>
        <limit><lower>-1e16</lower><upper>1e16</upper></limit>
      </axis>
    </joint>

    <!-- DiffDrive plugin -->
    <plugin filename="gz-sim-diff-drive-system"
            name="gz::sim::systems::DiffDrive">
      <left_joints>left_wheel_joint</left_joints>
      <right_joints>right_wheel_joint</right_joints>
      <wheel_separation>0.4</wheel_separation>
      <wheel_radius>0.05</wheel_radius>
      <topic>/model/diffdrive_robot/cmd_vel</topic>
    </plugin>
  </model>
</sdf>
